<?xml version="1.0"?>
<robot xmlns:xacro="http://www.ros.org/wiki/xacro" name="robot">

    <link name="base_footprint">
    </link>
    <link name="base_link">
        <visual>
            <geometry>
                <!-- <mesh filename="package://pkg_name/meshes/file_name"/> -->
                <box size="1.0 1.0 .1" />
                <!-- <cylinder radius="1.0" length="1.0"/> -->
            </geometry>
            <material name="blue">
                <color rgba="0.0 0.0 0.7 1.0"/>
            </material>
        </visual>
        <collision>
            <geometry>
                <!-- <mesh filename="package://pkg_name/meshes/file_name"/> -->
                <box size="1.0 1.0 .1" />
                <!-- <cylinder radius="1.0" length="1.0"/> -->
            </geometry>
        </collision>
        <inertial>
            <mass value="1.0"/>
            <origin xyz="0.0 0.0 0.0" rpy="0.0 0.0 0.0"/>
            <inertia ixx="0.084166" ixy="0.0" ixz="0.0" iyy="0.084166" iyz="0.0" izz="0.16666"/>
        </inertial>
    </link>

    <joint name="base_link_joint" type="fixed">
        <origin xyz="0.0 0.0 0.0" rpy="0.0 0.0 0.0"/>
        <parent link="base_footprint"/>
        <child link="base_link"/>
        <axis xyz="0.0 0.0 0.0"/>
    </joint>
    <xacro:macro name="wheel" params="name x y z">
        <link name="${name}">
            <visual>
                <geometry>
                    <!-- <mesh filename="package://pkg_name/meshes/file_name"/> -->
                    <!-- <box size="1.0 1.0 1.0" /> -->
                    <cylinder radius=".2" length="0.1"/>
                </geometry>
                <material name="red">
                    <color rgba="0.7 0.0 0.0 1.0"/>
                </material>
            </visual>
            <collision>
                <geometry>
                    <!-- <mesh filename="package://pkg_name/meshes/file_name"/> -->
                    <!-- <box size="1.0 1.0 1.0" /> -->
                    <cylinder radius=".2" length=".1"/>
                </geometry>
            </collision>
            <inertial>
                <mass value="0.5"/>
                <origin xyz="0.0 0.0 0.0" rpy="0.0 0.0 0.0"/>
                <inertia ixx="0.0054158" ixy="0.0" ixz="0.0" iyy="0.0054158" iyz="0.0" izz="0.01"/>
            </inertial>
        </link>
        <joint name="wheel_${name}_joint" type="continuous">
            <parent link="base_link"/>
            <child link="${name}"/>
            <axis xyz="0 0 1"/>
            <origin xyz="${x} ${y} ${z}" rpy="1.57 0 0"/>
        </joint> 
    </xacro:macro>
    
    <!-- <xacro:include filename="$(find lab3_sub_pub)/description/laser_plugin.xacro"/> -->
    <xacro:include filename="$(find lab3_sub_pub)/description/robot_controller.xacro"/>
    

    <xacro:wheel name="front_right" x="0.389898" y="-0.541621" z="0.000419"/>
    <xacro:wheel name="front_left" x="0.389898" y="0.541621" z="-0.000419"/>
    <xacro:wheel name="back_right" x="-0.389898" y="-0.541621" z="0.000419"/>
    <xacro:wheel name="back_left" x="-0.389898" y="0.541621" z="-0.000419"/>
    
</robot>
